{"name": "Var olan medya hesabını güncelleme işleminin kontrolü", "status": "failed", "statusDetails": {"message": "AssertionError: ++++ soft assert failure details follow below ++++\n\n++++++++++++++++++++++++++++++++++++++++++++++++++++++++++++++++++++++\nThe following failure was found in \"test_medya_hesabi_guncelle\" (test_medya_hesaplarim.TestTobetoMedyaHesaplarim):\n+----------------------+----------------------+----------------------+\nTraceback (most recent call last):\n  File \"/Users/zehra/Documents/GitHub/test_tobeto/tests/test_medya_hesaplarim.py\", line 96, in test_medya_hesabi_guncelle\n    self.soft_assert(self.assertEqual, MEDIA_UPDATE_SUCCESS_TEXT, medya_hesaplarim.guncelleme_islemini_gerceklestir(), \"• Forbidden\")\n  File \"/Library/Frameworks/Python.framework/Versions/3.11/lib/python3.11/site-packages/softest/case.py\", line 62, in soft_assert\n    assert_method(*arguments, **keywords)\n  File \"/Library/Frameworks/Python.framework/Versions/3.11/lib/python3.11/unittest/case.py\", line 873, in assertEqual\n    assertion_func(first, second, msg=msg)\n  File \"/Library/Frameworks/Python.framework/Versions/3.11/lib/python3.11/unittest/case.py\", line 1253, in assertMultiLineEqual\n    self.fail(self._formatMessage(msg, standardMsg))\n  File \"/Library/Frameworks/Python.framework/Versions/3.11/lib/python3.11/unittest/case.py\", line 703, in fail\n    raise self.failureException(msg)\nAssertionError: 'Başarıyla güncellendi.' != '• Forbidden'\n- Başarıyla güncellendi.\n+ • Forbidden\n : • Forbidden\n\n-+ [1/1] +-", "trace": "self = <test_medya_hesaplarim.TestTobetoMedyaHesaplarim testMethod=test_medya_hesabi_guncelle>\n\n    @allure.title(\"Var olan medya hesabını güncelleme işleminin kontrolü\")\n    def test_medya_hesabi_guncelle(self):\n        giris = Giris(self.driver)\n        yabanci_dillerim = Yabanci_dil_ekle(self.driver)\n        medya_hesaplarim = Medya_hesabi_guncelle(self.driver)\n    \n        giris.ana_giris()\n        yabanci_dillerim.profilim_kismina_tikla()\n        yabanci_dillerim.profil_bilgileri_tikla()\n        medya_hesaplarim.medya_hesaplarima_tikla()\n        medya_hesaplarim.guncelle_butonuna_tikla()\n        medya_hesaplarim.acilir_menu_tikla()\n        medya_hesaplarim.medya_hesabi_sec()\n        medya_hesaplarim.medya_url_gir()\n        medya_hesaplarim.medya_guncelle()\n        self.soft_assert(self.assertEqual, MEDIA_UPDATE_SUCCESS_TEXT, medya_hesaplarim.guncelleme_islemini_gerceklestir(), \"• Forbidden\")\n        pyautogui.screenshot(UPDATE_MEDIA_SCRRENSHOT_PATH)\n>       self.assert_all()\n\ntests/test_medya_hesaplarim.py:98: \n_ _ _ _ _ _ _ _ _ _ _ _ _ _ _ _ _ _ _ _ _ _ _ _ _ _ _ _ _ _ _ _ _ _ _ _ _ _ _ _ _ _ _ _ _ _ _ _ _ _ _ _ _ _ _\n/Library/Frameworks/Python.framework/Versions/3.11/lib/python3.11/site-packages/softest/case.py:139: in assert_all\n    self.fail(''.join(failure_output))\nE   AssertionError: ++++ soft assert failure details follow below ++++\nE   \nE   ++++++++++++++++++++++++++++++++++++++++++++++++++++++++++++++++++++++\nE   The following failure was found in \"test_medya_hesabi_guncelle\" (test_medya_hesaplarim.TestTobetoMedyaHesaplarim):\nE   +----------------------+----------------------+----------------------+\nE   Traceback (most recent call last):\nE     File \"/Users/zehra/Documents/GitHub/test_tobeto/tests/test_medya_hesaplarim.py\", line 96, in test_medya_hesabi_guncelle\nE       self.soft_assert(self.assertEqual, MEDIA_UPDATE_SUCCESS_TEXT, medya_hesaplarim.guncelleme_islemini_gerceklestir(), \"• Forbidden\")\nE     File \"/Library/Frameworks/Python.framework/Versions/3.11/lib/python3.11/site-packages/softest/case.py\", line 62, in soft_assert\nE       assert_method(*arguments, **keywords)\nE     File \"/Library/Frameworks/Python.framework/Versions/3.11/lib/python3.11/unittest/case.py\", line 873, in assertEqual\nE       assertion_func(first, second, msg=msg)\nE     File \"/Library/Frameworks/Python.framework/Versions/3.11/lib/python3.11/unittest/case.py\", line 1253, in assertMultiLineEqual\nE       self.fail(self._formatMessage(msg, standardMsg))\nE     File \"/Library/Frameworks/Python.framework/Versions/3.11/lib/python3.11/unittest/case.py\", line 703, in fail\nE       raise self.failureException(msg)\nE   AssertionError: 'Başarıyla güncellendi.' != '• Forbidden'\nE   - Başarıyla güncellendi.\nE   + • Forbidden\nE    : • Forbidden\nE   \nE   -+ [1/1] +-"}, "start": 1714735259417, "stop": 1714735292040, "uuid": "0cfbefc1-fdb7-40ea-b978-94a79dddd496", "historyId": "cdeda1a0b4a7fb0415fcf822b1786d87", "testCaseId": "cdeda1a0b4a7fb0415fcf822b1786d87", "fullName": "tests.test_medya_hesaplarim.TestTobetoMedyaHesaplarim#test_medya_hesabi_guncelle", "labels": [{"name": "tag", "value": "@pytest.mark.usefixtures('setup')"}, {"name": "parentSuite", "value": "tests"}, {"name": "suite", "value": "test_medya_hesaplarim"}, {"name": "subSuite", "value": "TestTobetoMedyaHesaplarim"}, {"name": "host", "value": "ZEHRA-MacBook-Air.local"}, {"name": "thread", "value": "45014-MainThread"}, {"name": "framework", "value": "pytest"}, {"name": "language", "value": "cpython3"}, {"name": "package", "value": "tests.test_medya_hesaplarim"}]}