{"name": "Bilgiler boş geçildiginde uyari mesaji alma kontrolü", "status": "failed", "statusDetails": {"message": "AssertionError: ++++ soft assert failure details follow below ++++\n\n++++++++++++++++++++++++++++++++++++++++++++++++++++++++++++++++++++++\nThe following failure was found in \"test2_bilgiler_bos_gecildiginde_uyari_meajlari_goruntulenmesi_FAIL\" (test_kayit_ol.TestKayitOl):\n+----------------------+----------------------+----------------------+\nTraceback (most recent call last):\n  File \"/Users/standard/Desktop/Tobeto-Test-Team-Project/tests/test_kayit_ol.py\", line 28, in test2_bilgiler_bos_gecildiginde_uyari_meajlari_goruntulenmesi_FAIL\n    self.soft_assert(self.assertEqual, beklenen_zorunlu_alan_sayisi, kayit_ol_object.zorunlu_alan_karsilastirma(), \"BEKLENILEN POPUP GORUNTULENMEDI.\")\n  File \"/Library/Frameworks/Python.framework/Versions/3.12/lib/python3.12/site-packages/softest/case.py\", line 62, in soft_assert\n    assert_method(*arguments, **keywords)\n  File \"/Library/Frameworks/Python.framework/Versions/3.12/lib/python3.12/unittest/case.py\", line 887, in assertEqual\n    assertion_func(first, second, msg=msg)\n  File \"/Library/Frameworks/Python.framework/Versions/3.12/lib/python3.12/unittest/case.py\", line 880, in _baseAssertEqual\n    raise self.failureException(msg)\nAssertionError: 5 != 1 : BEKLENILEN POPUP GORUNTULENMEDI.\n\n-+ [1/1] +-", "trace": "self = <test_kayit_ol.TestKayitOl testMethod=test2_bilgiler_bos_gecildiginde_uyari_meajlari_goruntulenmesi_FAIL>\n\n    @allure.title(\"Bilgiler boş geçildiginde uyari mesaji alma kontrolü\")\n    def test2_bilgiler_bos_gecildiginde_uyari_meajlari_goruntulenmesi_FAIL(self):\n        kayit_ol_object = KayitOlFonksiyonu(self.driver)\n        kayit_ol_object.bos_kayit()\n        beklenen_zorunlu_alan_sayisi = int(5)\n        self.soft_assert(self.assertEqual, beklenen_zorunlu_alan_sayisi, kayit_ol_object.zorunlu_alan_karsilastirma(), \"BEKLENILEN POPUP GORUNTULENMEDI.\")\n>       self.assert_all()\n\ntests/test_kayit_ol.py:29: \n_ _ _ _ _ _ _ _ _ _ _ _ _ _ _ _ _ _ _ _ _ _ _ _ _ _ _ _ _ _ _ _ _ _ _ _ _ _ _ _ _ _ _ _ _ _ _ _ _ _ _ _ _ _ _ _ _ _ _ _ _ _ _ _ _ _ _ _ _ _ \n/Library/Frameworks/Python.framework/Versions/3.12/lib/python3.12/site-packages/softest/case.py:139: in assert_all\n    self.fail(''.join(failure_output))\nE   AssertionError: ++++ soft assert failure details follow below ++++\nE   \nE   ++++++++++++++++++++++++++++++++++++++++++++++++++++++++++++++++++++++\nE   The following failure was found in \"test2_bilgiler_bos_gecildiginde_uyari_meajlari_goruntulenmesi_FAIL\" (test_kayit_ol.TestKayitOl):\nE   +----------------------+----------------------+----------------------+\nE   Traceback (most recent call last):\nE     File \"/Users/standard/Desktop/Tobeto-Test-Team-Project/tests/test_kayit_ol.py\", line 28, in test2_bilgiler_bos_gecildiginde_uyari_meajlari_goruntulenmesi_FAIL\nE       self.soft_assert(self.assertEqual, beklenen_zorunlu_alan_sayisi, kayit_ol_object.zorunlu_alan_karsilastirma(), \"BEKLENILEN POPUP GORUNTULENMEDI.\")\nE     File \"/Library/Frameworks/Python.framework/Versions/3.12/lib/python3.12/site-packages/softest/case.py\", line 62, in soft_assert\nE       assert_method(*arguments, **keywords)\nE     File \"/Library/Frameworks/Python.framework/Versions/3.12/lib/python3.12/unittest/case.py\", line 887, in assertEqual\nE       assertion_func(first, second, msg=msg)\nE     File \"/Library/Frameworks/Python.framework/Versions/3.12/lib/python3.12/unittest/case.py\", line 880, in _baseAssertEqual\nE       raise self.failureException(msg)\nE   AssertionError: 5 != 1 : BEKLENILEN POPUP GORUNTULENMEDI.\nE   \nE   -+ [1/1] +-"}, "start": 1714825848112, "stop": 1714825879321, "uuid": "ef254b26-6506-46f4-a15a-58fbeb3369ae", "historyId": "0b50873283d6b7ecddbd4a75a28ac541", "testCaseId": "0b50873283d6b7ecddbd4a75a28ac541", "fullName": "tests.test_kayit_ol.TestKayitOl#test2_bilgiler_bos_gecildiginde_uyari_meajlari_goruntulenmesi_FAIL", "labels": [{"name": "tag", "value": "@pytest.mark.usefixtures('setup')"}, {"name": "parentSuite", "value": "tests"}, {"name": "suite", "value": "test_kayit_ol"}, {"name": "subSuite", "value": "TestKayitOl"}, {"name": "host", "value": "elif.local"}, {"name": "thread", "value": "5967-MainThread"}, {"name": "framework", "value": "pytest"}, {"name": "language", "value": "cpython3"}, {"name": "package", "value": "tests.test_kayit_ol"}]}