{"name": "Zorunlu alan kontrolu", "status": "failed", "statusDetails": {"message": "AssertionError: ++++ soft assert failure details follow below ++++\n\n++++++++++++++++++++++++++++++++++++++++++++++++++++++++++++++++++++++\nThe following failure was found in \"test_zorunlu_alanlar_eksik_girildiginde_hata_mesajlari_goruntulenir_fail\" (test_deneyimlerim.TestDeneyimlerim):\n+----------------------+----------------------+----------------------+\nTraceback (most recent call last):\n  File \"/Users/zehra/Documents/GitHub/test_tobeto/tests/test_deneyimlerim.py\", line 146, in test_zorunlu_alanlar_eksik_girildiginde_hata_mesajlari_goruntulenir_fail\n    self.soft_assert(self.assertEqual, beklenen_zorunlu_alan_sayisi , deneyimlerim.zorunlu_alan_hata_kontrolu(), \"BEKLENILEN POPUP GORUNTULENMEDI.\")\n  File \"/Library/Frameworks/Python.framework/Versions/3.11/lib/python3.11/site-packages/softest/case.py\", line 62, in soft_assert\n    assert_method(*arguments, **keywords)\n  File \"/Library/Frameworks/Python.framework/Versions/3.11/lib/python3.11/unittest/case.py\", line 873, in assertEqual\n    assertion_func(first, second, msg=msg)\n  File \"/Library/Frameworks/Python.framework/Versions/3.11/lib/python3.11/unittest/case.py\", line 866, in _baseAssertEqual\n    raise self.failureException(msg)\nAssertionError: 6 != 5 : BEKLENILEN POPUP GORUNTULENMEDI.\n\n-+ [1/1] +-", "trace": "self = <test_deneyimlerim.TestDeneyimlerim testMethod=test_zorunlu_alanlar_eksik_girildiginde_hata_mesajlari_goruntulenir_fail>\n\n    @allure.title(\"Zorunlu alan kontrolu\")\n    def test_zorunlu_alanlar_eksik_girildiginde_hata_mesajlari_goruntulenir_fail(self):\n        deneyimlerim= Deneyimlerim(self.driver)\n    \n        self.test_deneyimlerim_sayfasina_gider()\n        time.sleep(3)\n        deneyimlerim.kaydet_butonuna_tiklar()\n        time.sleep(3)\n        beklenen_zorunlu_alan_sayisi = int(6)\n        print(deneyimlerim.zorunlu_alan_hata_kontrolu())\n        self.soft_assert(self.assertEqual, beklenen_zorunlu_alan_sayisi , deneyimlerim.zorunlu_alan_hata_kontrolu(), \"BEKLENILEN POPUP GORUNTULENMEDI.\")\n>       self.assert_all()\n\ntests/test_deneyimlerim.py:147: \n_ _ _ _ _ _ _ _ _ _ _ _ _ _ _ _ _ _ _ _ _ _ _ _ _ _ _ _ _ _ _ _ _ _ _ _ _ _ _ _ _ _ _ _ _ _ _ _ _ _ _ _ _ _ _\n/Library/Frameworks/Python.framework/Versions/3.11/lib/python3.11/site-packages/softest/case.py:139: in assert_all\n    self.fail(''.join(failure_output))\nE   AssertionError: ++++ soft assert failure details follow below ++++\nE   \nE   ++++++++++++++++++++++++++++++++++++++++++++++++++++++++++++++++++++++\nE   The following failure was found in \"test_zorunlu_alanlar_eksik_girildiginde_hata_mesajlari_goruntulenir_fail\" (test_deneyimlerim.TestDeneyimlerim):\nE   +----------------------+----------------------+----------------------+\nE   Traceback (most recent call last):\nE     File \"/Users/zehra/Documents/GitHub/test_tobeto/tests/test_deneyimlerim.py\", line 146, in test_zorunlu_alanlar_eksik_girildiginde_hata_mesajlari_goruntulenir_fail\nE       self.soft_assert(self.assertEqual, beklenen_zorunlu_alan_sayisi , deneyimlerim.zorunlu_alan_hata_kontrolu(), \"BEKLENILEN POPUP GORUNTULENMEDI.\")\nE     File \"/Library/Frameworks/Python.framework/Versions/3.11/lib/python3.11/site-packages/softest/case.py\", line 62, in soft_assert\nE       assert_method(*arguments, **keywords)\nE     File \"/Library/Frameworks/Python.framework/Versions/3.11/lib/python3.11/unittest/case.py\", line 873, in assertEqual\nE       assertion_func(first, second, msg=msg)\nE     File \"/Library/Frameworks/Python.framework/Versions/3.11/lib/python3.11/unittest/case.py\", line 866, in _baseAssertEqual\nE       raise self.failureException(msg)\nE   AssertionError: 6 != 5 : BEKLENILEN POPUP GORUNTULENMEDI.\nE   \nE   -+ [1/1] +-"}, "attachments": [{"name": "stdout", "source": "10136a27-f492-454c-8b9d-03e4770737c1-attachment.txt", "type": "text/plain"}], "start": 1714816338765, "stop": 1714816365697, "uuid": "8edb60cc-36a3-4aee-97fe-2e0e6fdf47c6", "historyId": "c385127965cf2df7784c7bb916728ce0", "testCaseId": "c385127965cf2df7784c7bb916728ce0", "fullName": "tests.test_deneyimlerim.TestDeneyimlerim#test_zorunlu_alanlar_eksik_girildiginde_hata_mesajlari_goruntulenir_fail", "labels": [{"name": "tag", "value": "@pytest.mark.usefixtures('setup')"}, {"name": "parentSuite", "value": "tests"}, {"name": "suite", "value": "test_deneyimlerim"}, {"name": "subSuite", "value": "TestDeneyimlerim"}, {"name": "host", "value": "ZEHRA-MacBook-Air.local"}, {"name": "thread", "value": "49235-MainThread"}, {"name": "framework", "value": "pytest"}, {"name": "language", "value": "cpython3"}, {"name": "package", "value": "tests.test_deneyimlerim"}]}