{"name": "Kayitli bir tel no ile giris yapildiginda uyari meaji vermesinin kontrolu.", "status": "failed", "statusDetails": {"message": "AssertionError: ++++ soft assert failure details follow below ++++\n\n++++++++++++++++++++++++++++++++++++++++++++++++++++++++++++++++++++++\nThe following failure was found in \"test8_kayitli_telNo_uyari_mesaji_kontrolu_FAIL\" (test_kayit_ol.TestKayitOl):\n+----------------------+----------------------+----------------------+\nTraceback (most recent call last):\n  File \"/Users/standard/Desktop/Tobeto-Test-Team-Project/tests/test_kayit_ol.py\", line 79, in test8_kayitli_telNo_uyari_mesaji_kontrolu_FAIL\n    self.soft_assert(self.assertEqual, kayit_ol_object.mevcut_telNo_uyarisi_kontrolu(), MEVCUT_TELNO_UYARISI_TEXT, f\"BEKLENILEN POPUP GORUNTULENMEDI. Beklenen: {MEVCUT_TELNO_UYARISI_TEXT}\")\n  File \"/Library/Frameworks/Python.framework/Versions/3.12/lib/python3.12/site-packages/softest/case.py\", line 62, in soft_assert\n    assert_method(*arguments, **keywords)\n  File \"/Library/Frameworks/Python.framework/Versions/3.12/lib/python3.12/unittest/case.py\", line 887, in assertEqual\n    assertion_func(first, second, msg=msg)\n  File \"/Library/Frameworks/Python.framework/Versions/3.12/lib/python3.12/unittest/case.py\", line 1253, in assertMultiLineEqual\n    self.fail(self._formatMessage(msg, standardMsg))\n  File \"/Library/Frameworks/Python.framework/Versions/3.12/lib/python3.12/unittest/case.py\", line 717, in fail\n    raise self.failureException(msg)\nAssertionError: '' != 'Girdiginiz telefon numarasi ile kayitli uyelik bulunmaktadir.'\n+ Girdiginiz telefon numarasi ile kayitli uyelik bulunmaktadir.\n : BEKLENILEN POPUP GORUNTULENMEDI. Beklenen: Girdiginiz telefon numarasi ile kayitli uyelik bulunmaktadir.\n\n-+ [1/1] +-", "trace": "self = <test_kayit_ol.TestKayitOl testMethod=test8_kayitli_telNo_uyari_mesaji_kontrolu_FAIL>\n\n    @allure.title(\"Kayitli bir tel no ile giris yapildiginda uyari meaji vermesinin kontrolu.\")\n    def test8_kayitli_telNo_uyari_mesaji_kontrolu_FAIL(self):\n        kayit_ol_object = KayitOlFonksiyonu(self.driver)\n        kayit_ol_object.kayitOl_biliglerini_doldurur()\n        kayit_ol_object.mevcut_telNo_ile_sozlesmeler_sayfasi_doldurulur()\n        self.soft_assert(self.assertEqual, kayit_ol_object.mevcut_telNo_uyarisi_kontrolu(), MEVCUT_TELNO_UYARISI_TEXT, f\"BEKLENILEN POPUP GORUNTULENMEDI. Beklenen: {MEVCUT_TELNO_UYARISI_TEXT}\")\n>       self.assert_all()\n\ntests/test_kayit_ol.py:80: \n_ _ _ _ _ _ _ _ _ _ _ _ _ _ _ _ _ _ _ _ _ _ _ _ _ _ _ _ _ _ _ _ _ _ _ _ _ _ _ _ _ _ _ _ _ _ _ _ _ _ _ _ _ _ _ _ _ _ _ _ _ _ _ _ _ _ _ _ _ _ \n/Library/Frameworks/Python.framework/Versions/3.12/lib/python3.12/site-packages/softest/case.py:139: in assert_all\n    self.fail(''.join(failure_output))\nE   AssertionError: ++++ soft assert failure details follow below ++++\nE   \nE   ++++++++++++++++++++++++++++++++++++++++++++++++++++++++++++++++++++++\nE   The following failure was found in \"test8_kayitli_telNo_uyari_mesaji_kontrolu_FAIL\" (test_kayit_ol.TestKayitOl):\nE   +----------------------+----------------------+----------------------+\nE   Traceback (most recent call last):\nE     File \"/Users/standard/Desktop/Tobeto-Test-Team-Project/tests/test_kayit_ol.py\", line 79, in test8_kayitli_telNo_uyari_mesaji_kontrolu_FAIL\nE       self.soft_assert(self.assertEqual, kayit_ol_object.mevcut_telNo_uyarisi_kontrolu(), MEVCUT_TELNO_UYARISI_TEXT, f\"BEKLENILEN POPUP GORUNTULENMEDI. Beklenen: {MEVCUT_TELNO_UYARISI_TEXT}\")\nE     File \"/Library/Frameworks/Python.framework/Versions/3.12/lib/python3.12/site-packages/softest/case.py\", line 62, in soft_assert\nE       assert_method(*arguments, **keywords)\nE     File \"/Library/Frameworks/Python.framework/Versions/3.12/lib/python3.12/unittest/case.py\", line 887, in assertEqual\nE       assertion_func(first, second, msg=msg)\nE     File \"/Library/Frameworks/Python.framework/Versions/3.12/lib/python3.12/unittest/case.py\", line 1253, in assertMultiLineEqual\nE       self.fail(self._formatMessage(msg, standardMsg))\nE     File \"/Library/Frameworks/Python.framework/Versions/3.12/lib/python3.12/unittest/case.py\", line 717, in fail\nE       raise self.failureException(msg)\nE   AssertionError: '' != 'Girdiginiz telefon numarasi ile kayitli uyelik bulunmaktadir.'\nE   + Girdiginiz telefon numarasi ile kayitli uyelik bulunmaktadir.\nE    : BEKLENILEN POPUP GORUNTULENMEDI. Beklenen: Girdiginiz telefon numarasi ile kayitli uyelik bulunmaktadir.\nE   \nE   -+ [1/1] +-"}, "start": 1714826134869, "stop": 1714826186796, "uuid": "1326a9a7-e926-4ea8-a40a-235c57efc4b3", "historyId": "7dbeb71ad3091eb7e6894abef5d45f02", "testCaseId": "7dbeb71ad3091eb7e6894abef5d45f02", "fullName": "tests.test_kayit_ol.TestKayitOl#test8_kayitli_telNo_uyari_mesaji_kontrolu_FAIL", "labels": [{"name": "tag", "value": "@pytest.mark.usefixtures('setup')"}, {"name": "parentSuite", "value": "tests"}, {"name": "suite", "value": "test_kayit_ol"}, {"name": "subSuite", "value": "TestKayitOl"}, {"name": "host", "value": "elif.local"}, {"name": "thread", "value": "5967-MainThread"}, {"name": "framework", "value": "pytest"}, {"name": "language", "value": "cpython3"}, {"name": "package", "value": "tests.test_kayit_ol"}]}