{"name": "Mevcut bir eposta ile giris yapildıgında uyari mesaji kontrolü", "status": "failed", "statusDetails": {"message": "AssertionError: ++++ soft assert failure details follow below ++++\n\n++++++++++++++++++++++++++++++++++++++++++++++++++++++++++++++++++++++\nThe following failure was found in \"test5_mevcut_eposta_popup_goruntulenmesi_FAIL\" (test_kayit_ol.TestKayitOl):\n+----------------------+----------------------+----------------------+\nTraceback (most recent call last):\n  File \"/Users/standard/Desktop/Tobeto-Test-Team-Project/tests/test_kayit_ol.py\", line 51, in test5_mevcut_eposta_popup_goruntulenmesi_FAIL\n    self.soft_assert(self.assertEqual, kayit_ol_object.mevcut_eposta_popup_kontrolu(), MEVCUTSIFRE_TEXT, f\"BEKLENILEN POPUP GORUNTULENMEDI. Beklenen: {MEVCUTSIFRE_TEXT}\")\n  File \"/Library/Frameworks/Python.framework/Versions/3.12/lib/python3.12/site-packages/softest/case.py\", line 62, in soft_assert\n    assert_method(*arguments, **keywords)\n  File \"/Library/Frameworks/Python.framework/Versions/3.12/lib/python3.12/unittest/case.py\", line 887, in assertEqual\n    assertion_func(first, second, msg=msg)\n  File \"/Library/Frameworks/Python.framework/Versions/3.12/lib/python3.12/unittest/case.py\", line 1253, in assertMultiLineEqual\n    self.fail(self._formatMessage(msg, standardMsg))\n  File \"/Library/Frameworks/Python.framework/Versions/3.12/lib/python3.12/unittest/case.py\", line 717, in fail\n    raise self.failureException(msg)\nAssertionError: 'Kayıt oluşturmak için gerekli sözleşmeler[316 chars]m Et' != 'Girdiginiz eposta adresi ile kayitli uyel[13 chars]dir.'\n+ Girdiginiz eposta adresi ile kayitli uyelik bulunmaktadir.\n- Kayıt oluşturmak için gerekli sözleşmeler\n- Kişisel verileriniz Aydınlatma Metni kapsamında işlenmektedir.\n- Açık Rıza Metni’ni okudum ve anladım.*\n- Üyelik Sözleşmesi ve Kullanım Koşulları’nı okudum ve anladım.*\n- İletişim bilgilerim üzerinden pazarlama ve tanıtım amaçlı irtibata geçilmesini kabul ediyorum.\n- E-posta gönderim izni.*\n- Arama izni.*\n- Kapat\n- Devam Et\n : BEKLENILEN POPUP GORUNTULENMEDI. Beklenen: Girdiginiz eposta adresi ile kayitli uyelik bulunmaktadir.\n\n-+ [1/1] +-", "trace": "self = <test_kayit_ol.TestKayitOl testMethod=test5_mevcut_eposta_popup_goruntulenmesi_FAIL>\n\n    @allure.title(\"Mevcut bir eposta ile giris yapildıgında uyari mesaji kontrolü\")\n    def test5_mevcut_eposta_popup_goruntulenmesi_FAIL(self):\n         kayit_ol_object = KayitOlFonksiyonu(self.driver)\n         kayit_ol_object.mevcut_eposta_ile_kayit()\n         kayit_ol_object.mevcut_eposta_popup_kontrolu()\n         self.soft_assert(self.assertEqual, kayit_ol_object.mevcut_eposta_popup_kontrolu(), MEVCUTSIFRE_TEXT, f\"BEKLENILEN POPUP GORUNTULENMEDI. Beklenen: {MEVCUTSIFRE_TEXT}\")\n>        self.assert_all()\n\ntests/test_kayit_ol.py:52: \n_ _ _ _ _ _ _ _ _ _ _ _ _ _ _ _ _ _ _ _ _ _ _ _ _ _ _ _ _ _ _ _ _ _ _ _ _ _ _ _ _ _ _ _ _ _ _ _ _ _ _ _ _ _ _ _ _ _ _ _ _ _ _ _ _ _ _ _ _ _ \n/Library/Frameworks/Python.framework/Versions/3.12/lib/python3.12/site-packages/softest/case.py:139: in assert_all\n    self.fail(''.join(failure_output))\nE   AssertionError: ++++ soft assert failure details follow below ++++\nE   \nE   ++++++++++++++++++++++++++++++++++++++++++++++++++++++++++++++++++++++\nE   The following failure was found in \"test5_mevcut_eposta_popup_goruntulenmesi_FAIL\" (test_kayit_ol.TestKayitOl):\nE   +----------------------+----------------------+----------------------+\nE   Traceback (most recent call last):\nE     File \"/Users/standard/Desktop/Tobeto-Test-Team-Project/tests/test_kayit_ol.py\", line 51, in test5_mevcut_eposta_popup_goruntulenmesi_FAIL\nE       self.soft_assert(self.assertEqual, kayit_ol_object.mevcut_eposta_popup_kontrolu(), MEVCUTSIFRE_TEXT, f\"BEKLENILEN POPUP GORUNTULENMEDI. Beklenen: {MEVCUTSIFRE_TEXT}\")\nE     File \"/Library/Frameworks/Python.framework/Versions/3.12/lib/python3.12/site-packages/softest/case.py\", line 62, in soft_assert\nE       assert_method(*arguments, **keywords)\nE     File \"/Library/Frameworks/Python.framework/Versions/3.12/lib/python3.12/unittest/case.py\", line 887, in assertEqual\nE       assertion_func(first, second, msg=msg)\nE     File \"/Library/Frameworks/Python.framework/Versions/3.12/lib/python3.12/unittest/case.py\", line 1253, in assertMultiLineEqual\nE       self.fail(self._formatMessage(msg, standardMsg))\nE     File \"/Library/Frameworks/Python.framework/Versions/3.12/lib/python3.12/unittest/case.py\", line 717, in fail\nE       raise self.failureException(msg)\nE   AssertionError: 'Kayıt oluşturmak için gerekli sözleşmeler[316 chars]m Et' != 'Girdiginiz eposta adresi ile kayitli uyel[13 chars]dir.'\nE   + Girdiginiz eposta adresi ile kayitli uyelik bulunmaktadir.\nE   - Kayıt oluşturmak için gerekli sözleşmeler\nE   - Kişisel verileriniz Aydınlatma Metni kapsamında işlenmektedir.\nE   - Açık Rıza Metni’ni okudum ve anladım.*\nE   - Üyelik Sözleşmesi ve Kullanım Koşulları’nı okudum ve anladım.*\nE   - İletişim bilgilerim üzerinden pazarlama ve tanıtım amaçlı irtibata geçilmesini kabul ediyorum.\nE   - E-posta gönderim izni.*\nE   - Arama izni.*\nE   - Kapat\nE   - Devam Et\nE    : BEKLENILEN POPUP GORUNTULENMEDI. Beklenen: Girdiginiz eposta adresi ile kayitli uyelik bulunmaktadir.\nE   \nE   -+ [1/1] +-"}, "start": 1714825984163, "stop": 1714826015093, "uuid": "976c0d92-8450-4100-a885-f696df1c2f2a", "historyId": "455bdf0cf516d1aa632eb11a81750faa", "testCaseId": "455bdf0cf516d1aa632eb11a81750faa", "fullName": "tests.test_kayit_ol.TestKayitOl#test5_mevcut_eposta_popup_goruntulenmesi_FAIL", "labels": [{"name": "tag", "value": "@pytest.mark.usefixtures('setup')"}, {"name": "parentSuite", "value": "tests"}, {"name": "suite", "value": "test_kayit_ol"}, {"name": "subSuite", "value": "TestKayitOl"}, {"name": "host", "value": "elif.local"}, {"name": "thread", "value": "5967-MainThread"}, {"name": "framework", "value": "pytest"}, {"name": "language", "value": "cpython3"}, {"name": "package", "value": "tests.test_kayit_ol"}]}